Workbook

Sheet Made the Cut
A1: Domain Info | C1: Authority Metrics | I1: Referring Domains | L1: Backlinks | P1: Spam Score | Q1: Analysing Tools | R1: Ratios | U1: Additional Metrics | Y1: Language Metrics | Z1: Analysis
A2: Name | B2: Potentially spam | C2: DA | D2: AS | E2: DR | F2: UR | G2: TF | H2: CF | I2: S RD | J2: M RD | K2: A RD | L2: S BL | M2: M BL | N2: A BL | O2: IP'S | P2: SZ | Q2: Variance | R2: Follow % | S2: S (BL/RD) | T2: M (BL/RD) | U2: Age | V2: Indexed | W2: Drops | X2: MT | Y2: English % | Z2: Suitability | AA2: History | AB2: Expiry
A3: Name | B3: Potentially spam | C3: DA | D3: AS | E3: DR | F3: UR | G3: TF | H3: CF | I3: S RD | J3: M RD | K3: A RD | L3: S BL | M3: M BL | N3: A BL | O3: IP'S | P3: SZ | Q3: Variance | R3: Follow % | S3: S (BL/RD) | T3: M (BL/RD) | U3: Age | V3: Indexed | W3: Drops | X3: MT | Y3: English % | Z3: Suitability | AA3: History | AB3: Expiry
A4: 350brewing.com | C4: 37 | D4: 5 | E4: 15 | F4: 13 | G4: 12 | H4: 19 | I4: 160 | J4: 91 | K4: 188 | L4: 728 | M4: 186 | N4: 483 | O4: 200 | P4: 0 | Q4: 115 | R4: 0.64275862 | S4: 5 | T4: 2 | U4: 10 | V4: 1 | W4: 0 | X4: Arts/Visual Arts: 12 Recreation/Travel: 7 | Y4: 99.2 | AB4: 04/09/2025 20:31:00
A5: 99nbrs.com | C5: 19 | D5: 5 | E5: 18 | F5: 7 | G5: 6 | H5: 10 | I5: 97 | J5: 64 | K5: 131 | L5: 195 | M5: 112 | N5: 420 | O5: 104 | P5: 0 | Q5: 35 | R5: 0.55102041 | S5: 2 | T5: 2 | U5: 5 | V5: 1 | W5: 0 | X5: Arts: 6 Arts/Literature: 6 Arts/Photography: 5 Arts/Music: 4 News/Media Industry: 4 Recreation/Travel: 4 Society/Organizations: 4 | Y5: 97.1 | AB5: 04/16/2025 19:55:00
A6: acupuncture-fertility.org | C6: 19 | D6: 5 | E6: 46 | F6: 7 | G6: 20 | H6: 22 | I6: 228 | J6: 97 | K6: 222 | L6: 518 | M6: 360 | N6: 1357 | O6: 187 | P6: 8 | Q6: 175 | R6: 0.85135135 | S6: 2 | T6: 4 | U6: 18 | V6: 8 | W6: 1 | X6: Computers/Software/Internet: 20 Health/Alternative: 18 Regional/Europe: 14 Computers/Software/Operating Systems: 12 Arts/Performing Arts: 12 Society/Politics: 11 Health/Mental Health: 11 Computers/Internet/On the Web: 10 Recreation/Food: 10 | Y6: 96.5 | AB6: 04/08/2025 18:41:00
A7: aepnetworks.com | C7: 32 | D7: 20 | E7: 40 | F7: 6 | G7: 30 | H7: 27 | I7: 208 | J7: 143 | K7: 219 | L7: 817 | M7: 581 | N7: 1533 | O7: 222 | P7: 0 | Q7: 43 | R7: 0.83843329 | S7: 4 | T7: 4 | U7: 20 | V7: 5 | W7: 2 | X7: Computers/Security: 30 Computers/Intranet: 19 Computers/Consultants: 18 Computers/Internet/Searching: 14 | Y7: 93.2 | AB7: 04/12/2025 16:43:00
A8: affordablehealthca.com | C8: 35 | D8: 12 | E8: 24 | F8: 0 | G8: 11 | H8: 12 | I8: 156 | J8: 37 | K8: 171 | L8: 527 | M8: 64 | N8: 465 | O8: 157 | P8: 10 | Q8: 89 | R8: 0.43478261 | S8: 3 | T8: 2 | U8: 12 | V8: 147 | W8: 2 | X8: Arts/Weblogs: 11 Society/People: 8 Arts/Literature: 7 Computers/Programming/Languages: 6 | Y8: 95.1 | AB8: 04/13/2025 19:11:00
A9: agelessalliance.org | C9: 36 | D9: 5 | E9: 31 | F9: 22 | G9: 14 | H9: 17 | I9: 134 | J9: 50 | K9: 123 | L9: 617 | M9: 117 | N9: 273912 | O9: 154 | P9: 0 | Q9: 129 | R9: 0.46579805 | S9: 5 | T9: 2 | U9: 11 | V9: 1 | W9: 1 | X9: Health: 13 Society/People: 13 Regional/North America: 13 Society/Issues: 9 Reference/Education: 8 Health/Senior Health: 7 | Y9: 97.5 | AB9: 04/17/2025 16:36:00
A10: aifdr.org | C10: 25 | D10: 6 | E10: 33 | F10: 0 | G10: 14 | H10: 18 | I10: 196 | J10: 76 | K10: 171 | L10: 569 | M10: 174 | N10: 463 | O10: 222 | P10: 8 | Q10: 85 | R10: 0.5940246 | S10: 3 | T10: 2 | U10: 16 | V10: 314 | W10: 1 | X10: Science/Social Sciences: 14 | Y10: 74.2 | AB10: 04/17/2025 20:55:00
A11: akalpinelodge.com | C11: 24 | D11: 5 | E11: 19 | F11: 0 | G11: 24 | H11: 15 | I11: 97 | J11: 60 | K11: 94 | L11: 180 | M11: 85 | N11: 163 | O11: 104 | P11: 10 | Q11: 50 | R11: 0.78888889 | S11: 2 | T11: 1 | U11: 18 | V11: 1 | W11: 0 | X11: Recreation/Travel: 24 | Y11: 93.5 | AB11: 04/10/2025 16:48:00
A12: alfredospizzanc.com | C12: 24 | D12: 20 | E12: 14 | F12: 5 | G12: 12 | H12: 15 | I12: 86 | J12: 29 | K12: 77 | L12: 272 | M12: 46 | N12: 185 | O12: 109 | P12: 7 | Q12: 19 | R12: 0.64102564 | S12: 3 | T12: 2 | U12: 18 | V12: 6 | W12: 0 | X12: Recreation/Travel: 12 Recreation/Food: 11 Sports/Baseball: 10 | Y12: 100 | AB12: 04/15/2025 16:38:00
A13: almightyballer.com | B13: Video game industry; SEMrush backlink/RD ratio > 10 | C13: 34 | D13: 5 | E13: 24 | F13: 0 | G13: 11 | H13: 17 | I13: 101 | J13: 56 | K13: 136 | L13: 1266 | M13: 409 | N13: 1557 | O13: 145 | P13: 0 | Q13: 102 | R13: 0.53137411 | S13: 13 | T13: 7 | U13: 10 | V13: 4 | W13: 0 | X13: Games/Video Games/Sports: 10 Sports/Basketball: 9 | Y13: 100 | AB13: 04/10/2025 17:44:00
A14: alovelinksplus.com | C14: 30 | D14: 5 | E14: 23 | F14: 7 | G14: 20 | H14: 20 | I14: 361 | J14: 181 | K14: 367 | L14: 1881 | M14: 838 | N14: 5286 | O14: 311 | P14: 0 | Q14: 67 | R14: 0.59300477 | S14: 5 | T14: 5 | U14: 26 | V14: 4 | W14: 0 | X14: Arts/Performing Arts: 18 Society/Subcultures: 18 Computers/Usenet: 17 Home/Cooking: 17 Society/Relationships: 17 Society/Holidays: 16 Society/Philosophy: 13 Shopping/Jewelry: 10 | Y14: 89.1 | AB14: 04/13/2025 20:49:00
A15: apimeme.com | C15: 16 | D15: 16 | E15: 16 | F15: 9 | G15: 9 | H15: 18 | I15: 128 | J15: 27 | K15: 112 | L15: 369 | M15: 267 | N15: 291 | O15: 118 | P15: 0 | Q15: 10 | R15: 0.55826558 | S15: 3 | T15: 10 | U15: 11 | V15: 13300 | W15: 0 | X15: Computers/Systems: 9 Computers/Internet/Web Design and Development: 8 News/Media Industry: 7 Computers/Programming/Languages: 6 | Y15: 97.7 | AB15: 04/09/2025 20:05:00
A16: argenteam.net | C16: 46 | D16: 21 | E16: 31 | F16: 21 | G16: 19 | H16: 31 | I16: 1098 | J16: 538 | K16: 1363 | L16: 7457 | M16: 4023 | N16: 76144 | O16: 716 | P16: 0 | Q16: 92 | R16: 0.73407388 | S16: 7 | T16: 7 | U16: 22 | V16: 1 | W16: 1 | X16: Computers/Internet/Searching: 19 Arts/Literature: 10 | Y16: 60.5 | AB16: 04/14/2025 18:20:00
A17: asclme.org | B17: SEMrush backlink/RD ratio > 10 | C17: 31 | D17: 5 | E17: 26 | F17: 0 | G17: 27 | H17: 25 | I17: 285 | J17: 164 | K17: 195 | L17: 3823 | M17: 1138 | N17: 1930 | O17: 279 | P17: 4 | Q17: 83 | R17: 0.89722803 | S17: 13 | T17: 7 | U17: 17 | V17: 1 | W17: 1 | X17: Science/Earth Sciences: 27 Home/Cooking: 16 Health/Weight Loss: 14 Computers/Internet/Searching: 14 Health/Mental Health: 13 | Y17: 69.8 | AB17: 04/10/2025 17:45:00
A18: awesome80s.com | C18: 31 | D18: 5 | E18: 25 | F18: 24 | G18: 27 | H18: 23 | I18: 452 | J18: 697 | K18: 423 | L18: 2069 | M18: 1765 | N18: 5559 | O18: 530 | P18: 0 | Q18: 81 | R18: 0.83638996 | S18: 5 | T18: 3 | U18: 25 | V18: 1 | W18: 2 | X18: Arts/Music: 25 Society/History: 25 | Y18: 94 | AB18: 04/14/2025 17:12:00
A19: awny.org | C19: 39 | D19: 6 | E19: 40 | F19: 8 | G19: 15 | H19: 18 | I19: 219 | J19: 103 | K19: 230 | L19: 1183 | M19: 386 | N19: 1878 | O19: 220 | P19: 0 | Q19: 184 | R19: 0.82010135 | S19: 5 | T19: 4 | U19: 26 | V19: 1 | W19: 1 | X19: Society/Law: 15 Society/Issues: 12 Arts/Animation: 11 Society/People: 11 Business/Management: 9 Reference/Quotations: 9 Home/Family: 9 Arts/Architecture: 8 | Y19: 98.3 | AB19: 04/08/2025 18:58:00
A20: azurewi.com | C20: 21 | D20: 14 | E20: 22 | F20: 11 | G20: 10 | H20: 15 | I20: 793 | J20: 59 | K20: 417 | L20: 2420 | M20: 368 | N20: 1632 | O20: 699 | P20: 0 | Q20: 20 | R20: 0.84466419 | S20: 3 | T20: 6 | U20: 14 | V20: 270 | W20: 0 | X20: Regional/North America: 10 Reference/Education: 6 | Y20: 100 | AB20: 04/11/2025 19:05:00
A21: bartpark.com | C21: 37 | D21: 5 | E21: 31 | F21: 5 | G21: 29 | H21: 21 | I21: 305 | J21: 153 | K21: 338 | L21: 1122 | M21: 394 | N21: 1274 | O21: 290 | P21: 9 | Q21: 122 | R21: 0.69911504 | S21: 4 | T21: 3 | U21: 24 | V21: 1 | W21: 0 | X21: Recreation/Food: 29 | Y21: 92.2 | AB21: 04/12/2025 20:29:00
A22: basilicaofsaintpaul.com | C22: 17 | D22: 17 | E22: 11 | F22: 13 | G22: 22 | H22: 17 | I22: 169 | J22: 81 | K22: 184 | L22: 672 | M22: 96 | N22: 1097 | O22: 180 | P22: 2 | Q22: 12 | R22: 0.81547619 | S22: 4 | T22: 1 | U22: 19 | V22: 2 | W22: 0 | X22: Society/Religion and Spirituality: 22 | Y22: 93.5 | AB22: 04/16/2025 17:55:00
A23: batsurvey.org | C23: 25 | D23: 13 | E23: 31 | F23: 3 | G23: 17 | H23: 21 | I23: 143 | J23: 89 | K23: 133 | L23: 444 | M23: 174 | N23: 617 | O23: 156 | P23: 10 | Q23: 39 | R23: 0.62138085 | S23: 3 | T23: 2 | U23: 12 | V23: 62 | W23: 2 | X23: Recreation/Birding: 17 Home/Gardening: 12 Science/Biology: 11 Recreation/Outdoors: 9 | Y23: 96.3 | AB23: 04/08/2025 19:37:00
A24: bbbsheartga.org | C24: 25 | D24: 6 | E24: 37 | F24: 8 | G24: 13 | H24: 17 | I24: 87 | J24: 32 | K24: 87 | L24: 852 | M24: 61 | N24: 681 | O24: 111 | P24: 10 | Q24: 113 | R24: 0.96948357 | S24: 10 | T24: 2 | U24: 22 | V24: 8 | W24: 0 | X24: News/Magazines and E-zines: 13 Business/Hospitality: 9 Health/Mental Health: 8 News/Media Industry: 7 Society/Organizations: 7 | Y24: 100 | AB24: 04/14/2025 18:45:00
A25: beerandwinejournal.com | C25: 39 | D25: 5 | E25: 33 | F25: 10 | G25: 13 | H25: 26 | I25: 482 | J25: 720 | K25: 504 | L25: 3314 | M25: 2001 | N25: 5432 | O25: 450 | P25: 0 | Q25: 158 | R25: 0.51312217 | S25: 7 | T25: 3 | U25: 12 | V25: 1 | W25: 0 | X25: Recreation/Food: 13 Home/Cooking: 9 Society/Gay Lesbian and Bisexual: 7 | Y25: 85.3 | AB25: 04/11/2025 17:29:00
A26: bestofbridgestone.com | B26: Majestic backlink/RD ratio > 10 | C26: 33 | D26: 5 | E26: 36 | F26: 19 | G26: 26 | H26: 18 | I26: 166 | J26: 45 | K26: 149 | L26: 1736 | M26: 623 | N26: 10602 | O26: 181 | P26: 4 | Q26: 125 | R26: 0.96082949 | S26: 10 | T26: 14 | U26: 23 | V26: 1 | W26: 0 | X26: Recreation/Food: 26 Regional/Europe: 16 | Y26: 86.8 | AB26: 04/11/2025 18:08:00
A27: betway98.com | B27: Video game industry | C27: 23 | D27: 5 | E27: 29 | F27: 0 | G27: 11 | H27: 18 | I27: 170 | J27: 103 | K27: 280 | L27: 507 | M27: 177 | N27: 4478 | O27: 179 | P27: 0 | Q27: 72 | R27: 0.64566929 | S27: 3 | T27: 2 | U27: 9 | V27: 1 | W27: 0 | X27: Games/Video Games/Shooter: 11 Games/Video Games/Strategy: 10 Games/Video Games/News and Reviews: 10 Games/Video Games/Action: 10 Games/Video Games/Roleplaying: 10 Games/Video Games/Sports: 9 Games/Video Games/Driving and Racing: 9 Games/Video Games/Action-Adventure: 9 | Y27: 81.6 | AB27: 04/12/2025 16:04:00
A28: bgiedu.org | C28: 41 | D28: 5 | E28: 18 | F28: 26 | G28: 14 | H28: 28 | I28: 333 | J28: 209 | K28: 174 | L28: 1002 | M28: 773 | N28: 4095 | O28: 357 | P28: 0 | Q28: 153 | R28: 0.86327345 | S28: 3 | T28: 4 | U28: 22 | V28: 2 | W28: 1 | X28: Business/Textiles and Nonwovens: 13 Business/Real Estate: 12 Computers/Internet/On the Web: 10 Society/Issues: 9 Society/Paranormal: 9 Society/Subcultures: 7 Society/People: 7 | Y28: 99.3 | AB28: 04/11/2025 17:58:00
A29: biogenericpublishers.com | C29: 24 | D29: 16 | E29: 18 | F29: 6 | G29: 13 | H29: 17 | I29: 150 | J29: 59 | K29: 123 | L29: 728 | M29: 168 | N29: 2181 | O29: 152 | P29: 0 | Q29: 13 | R29: 0.94093407 | S29: 5 | T29: 3 | U29: 5 | V29: 1950 | W29: 0 | X29: Reference/Education: 13 Health/Fitness: 11 Health: 10 Reference/Libraries: 10 Health/Dentistry: 9 Science/Social Sciences: 9 Science/Biology: 9 Science/Technology: 8 Regional/South America: 7 Health/Medicine: 7 | Y29: 95.5 | AB29: 04/08/2025 21:26:00
A30: boomset.com | B30: Financial services industry | C30: 43 | D30: 6 | E30: 61 | F30: 0 | G30: 17 | H30: 26 | I30: 824 | J30: 467 | K30: 899 | L30: 7995 | M30: 2422 | N30: 20063 | O30: 982 | P30: 0 | Q30: 378 | R30: 0.65624609 | S30: 10 | T30: 5 | U30: 15 | V30: 2 | W30: 1 | X30: Business/Construction and Maintenance: 16 Business/Financial Services: 16 Recreation/Travel: 14 Computers/Software/Globalization: 12 Computers/Consultants: 12 Business/Arts and Entertainment: 12 Business: 12 Society/People: 12 Business/Electronics and Electrical: 10 Society/Issues: 10 | Y30: 95.6 | AB30: 04/14/2025 17:22:00
A31: borkurart.com | B31: SEMrush backlink/RD ratio > 10 | C31: 32 | D31: 5 | E31: 22 | F31: 30 | G31: 12 | H31: 15 | I31: 294 | J31: 38 | K31: 149 | L31: 5041 | M31: 431 | N31: 3208 | O31: 384 | P31: 0 | Q31: 85 | R31: 0.96664019 | S31: 17 | T31: 11 | U31: 16 | V31: 1 | W31: 0 | X31: Arts/Architecture: 12 | Y31: 68.2 | AB31: 04/10/2025 18:33:00
A32: britishcomicawards.com | C32: 34 | D32: 6 | E32: 23 | F32: 16 | G32: 15 | H32: 21 | I32: 224 | J32: 337 | K32: 228 | L32: 1304 | M32: 1007 | N32: 3806 | O32: 243 | P32: 0 | Q32: 85 | R32: 0.68091603 | S32: 6 | T32: 3 | U32: 13 | V32: 122 | W32: 1 | X32: Science/Math: 15 Arts/Comics: 12 Arts/Performing Arts: 12 Arts/Music: 11 | Y32: 99.2 | AB32: 04/10/2025 21:28:00
A33: buildingartisansguild.com | B33: Majestic backlink/RD ratio > 10 | C33: 19 | D33: 5 | E33: 53 | F33: 5 | G33: 23 | H33: 19 | I33: 180 | J33: 73 | K33: 195 | L33: 707 | M33: 947 | N33: 8953 | O33: 182 | P33: 0 | Q33: 251 | R33: 0.75035261 | S33: 4 | T33: 13 | U33: 13 | V33: 253 | W33: 1 | X33: Business: 23 | Y33: 100 | AB33: 04/10/2025 16:13:00
A34: bushcommission.org | C34: 31 | D34: 5 | E34: 10 | F34: 17 | G34: 18 | H34: 24 | I34: 287 | J34: 170 | K34: 376 | L34: 1904 | M34: 1483 | N34: 9043 | O34: 264 | P34: 0 | Q34: 87 | R34: 0.9269958 | S34: 7 | T34: 9 | U34: 16 | V34: 1 | W34: 2 | X34: Society/Activism: 17 Arts/Crafts: 16 Society/Issues: 16 Society/Politics: 16 Society/Government: 11 Society/People: 11 Computers/Internet/Web Design and Development: 10 Business/Food and Related Products: 10 Business/Industrial Goods and Services: 10 Games/Board Games: 10 | Y34: 61.3 | AB34: 04/09/2025 17:14:00
A35: calobonga.com | C35: 22 | D35: 5 | E35: 21 | F35: 0 | G35: 11 | H35: 16 | I35: 177 | J35: 86 | K35: 166 | L35: 1150 | M35: 248 | N35: 1624 | O35: 159 | P35: 7 | Q35: 40 | R35: 0.68549088 | S35: 6 | T35: 3 | U35: 15 | V35: 1 | W35: 0 | X35: Recreation/Food: 11 | Y35: 73.9 | AB35: 04/09/2025 19:05:00
A36: camdenabudis.net | C36: 30 | D36: 5 | E36: 16 | F36: 0 | G36: 10 | H36: 17 | I36: 203 | J36: 83 | K36: 185 | L36: 387 | M36: 154 | N36: 3614 | O36: 178 | P36: 0 | Q36: 71 | R36: 0.70542636 | S36: 2 | T36: 2 | U36: 16 | V36: 1 | W36: 2 | X36: Arts/Music: 10 | Y36: 91.9 | AB36: 04/16/2025 18:41:00
A37: carnegiestones.com | C37: 45 | D37: 5 | E37: 10 | F37: 12 | G37: 9 | H37: 17 | I37: 263 | J37: 56 | K37: 277 | L37: 386 | M37: 211 | N37: 996 | O37: 236 | P37: 0 | Q37: 208 | R37: 0.85233161 | S37: 1 | T37: 4 | U37: 14 | V37: 116 | W37: 2 | X37: News/Media Industry: 9 News/Directories: 5 | Y37: 65 | AB37: 04/10/2025 16:31:00
A38: carryingonproject.org | C38: 19 | D38: 5 | E38: 25 | F38: 0 | G38: 8 | H38: 15 | I38: 108 | J38: 77 | K38: 131 | L38: 221 | M38: 156 | N38: 339 | O38: 120 | P38: 11 | Q38: 53 | R38: 0.86425339 | S38: 2 | T38: 2 | U38: 12 | V38: 1 | W38: 0 | X38: Shopping/Holidays: 8 Society/Organizations: 7 Society: 7 Reference/Education: 7 Home/Entertaining: 6 Society/Work: 6 Arts/People: 6 Society/Military: 6 Regional/North America: 6 Health/Alternative: 5 | Y38: 100 | AB38: 04/12/2025 21:15:00
A39: cascadiafest.org | C39: 22 | D39: 5 | E39: 21 | F39: 0 | G39: 19 | H39: 19 | I39: 91 | J39: 41 | K39: 89 | L39: 340 | M39: 150 | N39: 2308 | O39: 106 | P39: 0 | Q39: 39 | R39: 0.90643275 | S39: 4 | T39: 4 | U39: 9 | V39: 2 | W39: 0 | X39: Computers/Programming/Languages: 19 Computers/Internet/Web Design and Development: 11 | Y39: 97.8 | AB39: 04/09/2025 18:07:00
A40: cathlametchamber.com | C40: 23 | D40: 5 | E40: 22 | F40: 18 | G40: 13 | H40: 20 | I40: 721 | J40: 141 | K40: 100 | L40: 5464 | M40: 800 | N40: 526 | O40: 835 | P40: 0 | Q40: 46 | R40: 0.74678899 | S40: 8 | T40: 6 | U40: 14 | V40: 4 | W40: 0 | X40: Business/Small Business: 13 Business: 11 Business/International Business and Trade: 10 Business/Management: 10 Science/Social Sciences: 10 Business/Employment: 9 Regional/North America: 8 Recreation/Travel: 8 Reference/Education: 8 Society: 7 | Y40: 100 | AB40: 04/10/2025 16:24:00
...

Sheet Did Not Make the Cut
A1: Domain Info | C1: Authority Metrics | I1: Referring Domains | L1: Backlinks | P1: Spam Score | Q1: Analysing Tools | R1: Ratios | U1: Additional Metrics | Y1: Language Metrics | Z1: Analysis
A2: Name | B2: Reason | C2: DA | D2: AS | E2: DR | F2: UR | G2: TF | H2: CF | I2: S RD | J2: M RD | K2: A RD | L2: S BL | M2: M BL | N2: A BL | O2: IP'S | P2: SZ | Q2: Variance | R2: Follow % | S2: S (BL/RD) | T2: M (BL/RD) | U2: Age | V2: Indexed | W2: Drops | X2: MT | Y2: English % | Z2: Suitability | AA2: History | AB2: Expiry
A3: Name | B3: Reason | C3: DA | D3: AS | E3: DR | F3: UR | G3: TF | H3: CF | I3: S RD | J3: M RD | K3: A RD | L3: S BL | M3: M BL | N3: A BL | O3: IP'S | P3: SZ | Q3: Variance | R3: Follow % | S3: S (BL/RD) | T3: M (BL/RD) | U3: Age | V3: Indexed | W3: Drops | X3: MT | Y3: English % | Z3: Suitability | AA3: History | AB3: Expiry
A4: 1-stop-guide.com | B4: Authority Score too low: 2 (minimum 5 required) | C4: 15 | D4: 2 | E4: 33 | F4: 0 | G4: 23 | H4: 18 | I4: 76 | J4: 37 | K4: 68 | L4: 163 | M4: 856 | N4: 1768 | O4: 75 | P4: 0 | Q4: 103 | R4: 0.73006135 | S4: 2 | T4: 23 | U4: 26 | V4: 1 | W4: 1 | X4: Shopping/Vehicles: 23 | Y4: 100 | AB4: 04/12/2025 18:37:00
A5: 19nitten.com | B5: Prohibited topic: Adult content | C5: 27 | D5: 10 | E5: 18 | F5: 4 | G5: 20 | H5: 19 | I5: 132 | J5: 87 | K5: 120 | L5: 852 | M5: 1433 | N5: 7182 | O5: 98 | P5: 9 | Q5: 29 | R5: 0.86619718 | S5: 6 | T5: 16 | U5: 27 | V5: 1 | W5: 0 | X5: Adult/Image Galleries: 20 | Y5: 99.4 | AB5: 04/11/2025 18:36:00
A6: 23is-back.com | B6: Authority Score too low: 4 (minimum 5 required) | C6: 25 | D6: 4 | E6: 52 | F6: 19 | G6: 14 | H6: 20 | I6: 655 | J6: 410 | K6: 1247 | L6: 4577 | M6: 1893 | N6: 18351 | O6: 287 | P6: 0 | Q6: 259 | R6: 0.9556478 | S6: 7 | T6: 5 | U6: 5 | V6: 1 | W6: 0 | X6: Shopping: 13 Regional/Asia: 13 Recreation/Pets: 11 Arts/Music: 9 Shopping/Recreation: 8 | Y6: 21.4 | AB6: 04/13/2025 20:25:00
A7: 3dfilmfest.com | B7: Authority Score too low: 4 (minimum 5 required) | C7: 26 | D7: 4 | E7: 10 | F7: 14 | G7: 12 | H7: 20 | I7: 165 | J7: 320 | K7: 140 | L7: 682 | M7: 650 | N7: 1752 | O7: 193 | P7: 0 | Q7: 60 | R7: 0.50658858 | S7: 4 | T7: 2 | U7: 20 | V7: 1 | W7: 0 | X7: Society/People: 12 Arts/Movies: 10 Arts/Music: 8 Business/Arts and Entertainment: 7 | Y7: 95.6 | AB7: 04/11/2025 17:50:00
A8: 4orienteering.com | B8: SEMrush backlink/RD ratio too high: 34 (maximum 20); Majestic backlink/RD ratio too high: 40 (maximum 20) | C8: 26 | D8: 18 | E8: 29 | F8: 1 | G8: 27 | H8: 26 | I8: 174 | J8: 209 | K8: 213 | L8: 5996 | M8: 8365 | N8: 41675 | O8: 187 | P8: 3 | Q8: 14 | R8: 0.28241593 | S8: 34 | T8: 40 | U8: 21 | V8: 57 | W8: 0 | X8: Recreation/Food: 25 Sports/Orienteering: 23 Society/Issues: 20 | Y8: 100 | AB8: 04/13/2025 21:00:00
A9: aa-hall.com | B9: English percentage too low: 7.6% (minimum 60% required) | C9: 27 | D9: 5 | E9: 33 | F9: 0 | G9: 14 | H9: 16 | I9: 101 | J9: 39 | K9: 115 | L9: 269 | M9: 80 | N9: 278 | O9: 118 | P9: 0 | Q9: 98 | R9: 0.91449814 | S9: 3 | T9: 2 | U9: 23 | V9: 1 | W9: 0 | X9: Computers/Internet/Searching: 14 Computers/Software/Operating Systems: 9 | Y9: 7.6 | AB9: 04/13/2025 21:19:00
A10: acadianbus.com | B10: Authority Score too low: 3 (minimum 5 required) | C10: 30 | D10: 3 | E10: 17 | F10: 4 | G10: 19 | H10: 18 | I10: 118 | J10: 42 | K10: 122 | L10: 455 | M10: 165 | N10: 735 | O10: 141 | P10: 0 | Q10: 74 | R10: 0.78241758 | S10: 4 | T10: 4 | U10: 25 | V10: 1 | W10: 0 | X10: Recreation/Roads and Highways: 19 Business/Transportation and Logistics: 16 News/Media Industry: 15 Business: 11 Computers/Internet/Domain Names: 11 | Y10: 85 | AB10: 04/13/2025 17:41:00
A11: accessupseo.com | B11: Authority Score too low: 3 (minimum 5 required) | C11: 20 | D11: 3 | E11: 15 | F11: 0 | G11: 18 | H11: 18 | I11: 105 | J11: 57 | K11: 111 | L11: 206 | M11: 105 | N11: 220 | O11: 111 | P11: 0 | Q11: 37 | R11: 0.94660194 | S11: 2 | T11: 2 | U11: 16 | V11: 1 | W11: 0 | X11: Regional/Asia: 18 Arts/Performing Arts: 15 | Y11: 2.3 | AB11: 04/12/2025 16:57:00
A12: aebdistribuzioni.com | B12: English percentage too low: 15.3% (minimum 60% required); SEMrush backlink/RD ratio too high: 106 (maximum 20); Majestic backlink/RD ratio too high: 59 (maximum 20) | C12: 22 | D12: 5 | E12: 21 | F12: 0 | G12: 22 | H12: 17 | I12: 91 | J12: 39 | K12: 70 | L12: 9632 | M12: 2291 | N12: 9862 | O12: 77 | P12: 10 | Q12: 42 | R12: 0.98878505 | S12: 106 | T12: 59 | U12: 10 | V12: 30 | W12: 1 | X12: Business/Arts and Entertainment: 22 Arts/Music: 12 | Y12: 15.3 | AB12: 04/15/2025 18:56:00
A13: affordablehomesforsaleca.com | B13: Authority Score too low: 4 (minimum 5 required) | C13: 11 | D13: 4 | E13: 25 | F13: 34 | G13: 14 | H13: 17 | I13: 1147 | J13: 52 | K13: 172 | L13: 55071 | M13: 135 | N13: 911 | O13: 1167 | P13: 0 | Q13: 48 | R13: 0.99428011 | S13: 48 | T13: 3 | U13: 0 | V13: 1 | W13: 0 | X13: Business/Automotive: 14 | Y13: 86.8 | AB13: 04/12/2025 20:34:00
A14: ahlannet.com | B14: Authority Score too low: 4 (minimum 5 required) | C14: 9 | D14: 4 | E14: 10 | F14: 5 | G14: 7 | H14: 14 | I14: 61 | J14: 28 | K14: 58 | L14: 96 | M14: 489 | N14: 157 | O14: 65 | P14: 0 | Q14: 11 | R14: 0.78125 | S14: 2 | T14: 17 | U14: 18 | V14: 137 | W14: 0 | X14: Science/Chemistry: 7 | Y14: 100 | AB14: 04/10/2025 19:50:00
A15: aide-emploi.net | B15: English percentage too low: 47.7% (minimum 60% required) | C15: 32 | D15: 17 | E15: 18 | F15: 0 | G15: 24 | H15: 19 | I15: 345 | J15: 175 | K15: 322 | L15: 1522 | M15: 2423 | N15: 1212 | O15: 311 | P15: 3 | Q15: 31 | R15: 0.66732026 | S15: 4 | T15: 14 | U15: 24 | V15: 92 | W15: 1 | X15: Business/Employment: 24 Computers/Internet/Searching: 14 Regional/Europe: 13 Business: 12 Business/Real Estate: 12 | Y15: 47.7 | AB15: 04/14/2025 18:10:00
... A313: zozotheme.com | B313: Majestic backlink/RD ratio too high: 28 (maximum 20) | C313: 15 | D313: 14 | E313: 61 | F313: 17 | G313: 20 | H313: 29 | I313: 316 | J313: 124 | K313: 388 | L313: 4370 | M313: 3502 | N313: 5398 | O313: 357 | P313: 10 | Q313: 304 | R313: 0.90923676 | S313: 14 | T313: 28 | U313: 8 | V313: 1220 | W313: 0 | X313: Business/Construction and Maintenance: 20 | Y313: 74.9 | AB313: 04/16/2025 20:05:00

Sheet Suitability
A1: Domain Name | B1: Indexing | D1: SZ (export) | F1: SZ (interface) | H1: SEMRUSH | J1: Backlinks | L1: Archive | M1: Domain info
B2: Indexing - Indexed? | C2: Indexing - Site URL | D2: SZ (export) - Potential | E2: SZ (export) - Spam | F2: SZ (interface) - Potential | G2: SZ (interface) - Spam | H2: SEMRUSH - Potential | I2: SEMRUSH - Spam | J2: Backlinks - Potential | K2: Backlinks - Spam | L2: Archive - Clear? | M2: Domain info - Archive data
A3: 350brewing.com | C3: ="https://www.google.com/search?q=site:" & A3 -> https://www.google.com/search?q=site:350brewing.com | D3: dsv | E3: dv | F3: efe | H3: vds | I3: dv | J3: dd | K3: dsv | L3: dv | M3: =IFERROR(VLOOKUP(A3,History!A:B,2,FALSE),"")
A4: 99nbrs.com | C4: ="https://www.google.com/search?q=site:" & A4 -> https://www.google.com/search?q=site:99nbrs.com | M4: =IFERROR(VLOOKUP(A4,History!A:B,2,FALSE),"")
A5: acupuncture-fertility.org | C5: ="https://www.google.com/search?q=site:" & A5 -> https://www.google.com/search?q=site:acupuncture-fertility.org | M5: =IFERROR(VLOOKUP(A5,History!A:B,2,FALSE),"")
A6: aepnetworks.com | C6: ="https://www.google.com/search?q=site:" & A6 -> https://www.google.com/search?q=site:aepnetworks.com | M6: =IFERROR(VLOOKUP(A6,History!A:B,2,FALSE),"")
A7: affordablehealthca.com | C7: ="https://www.google.com/search?q=site:" & A7 -> https://www.google.com/search?q=site:affordablehealthca.com | M7: =IFERROR(VLOOKUP(A7,History!A:B,2,FALSE),"")
A8: agelessalliance.org | C8: ="https://www.google.com/search?q=site:" & A8 -> https://www.google.com/search?q=site:agelessalliance.org | M8: =IFERROR(VLOOKUP(A8,History!A:B,2,FALSE),"")
A9: aifdr.org | C9: ="https://www.google.com/search?q=site:" & A9 -> https://www.google.com/search?q=site:aifdr.org | M9: =IFERROR(VLOOKUP(A9,History!A:B,2,FALSE),"")
A10: akalpinelodge.com | C10: ="https://www.google.com/search?q=site:" & A10 -> https://www.google.com/search?q=site:akalpinelodge.com | M10: =IFERROR(VLOOKUP(A10,History!A:B,2,FALSE),"")
A11: alfredospizzanc.com | C11: ="https://www.google.com/search?q=site:" & A11 -> https://www.google.com/search?q=site:alfredospizzanc.com | M11: =IFERROR(VLOOKUP(A11,History!A:B,2,FALSE),"")
A12: almightyballer.com | C12: ="https://www.google.com/search?q=site:" & A12 -> https://www.google.com/search?q=site:almightyballer.com | M12: =IFERROR(VLOOKUP(A12,History!A:B,2,FALSE),"")
A13: alovelinksplus.com | C13: ="https://www.google.com/search?q=site:" & A13 -> https://www.google.com/search?q=site:alovelinksplus.com | M13: =IFERROR(VLOOKUP(A13,History!A:B,2,FALSE),"")
A14: apimeme.com | C14: ="https://www.google.com/search?q=site:" & A14 -> https://www.google.com/search?q=site:apimeme.com | M14: =IFERROR(VLOOKUP(A14,History!A:B,2,FALSE),"")
A15: argenteam.net | C15: ="https://www.google.com/search?q=site:" & A15 -> https://www.google.com/search?q=site:argenteam.net | M15: =IFERROR(VLOOKUP(A15,History!A:B,2,FALSE),"")
... A184: zebraimaging.com | C184: ="https://www.google.com/search?q=site:" & A184 -> https://www.google.com/search?q=site:zebraimaging.com | M184: =IFERROR(VLOOKUP(A184,History!A:B,2,FALSE),"")

Sheet Bidding Analysis
A1: Domain Name | B1: USD | C1: AUD | D1: Bids | E1: Expiry

Sheet History
A1: Domain Name | B1: Content | C1: Transferrals | D1: Drop History
